Workbook

Sheet sizing
C1: Workload (TPS) | D1: Core per Server | E1: Max Server Faults | F1: HA Ratio
C2: 8000 | D2: ='x86 TCO'!G5 -> 40 | E2: 2 | F2: =E4/D4 -> 0.2
B3: Typical core Ratio | C3: TPS by Core | D3: # of Cores for workload TPS | E3: HA cores | F3: Prod cores | H3: Dev % of Workload | I3: Dev cores | J3: Test % of Workload | K3: Test cores | L3: PreProd % of Workload | M3: PreProd cores | N3: DR active cores % of Prod+PreProd | O3: DR cores | P3: DR CBU (spare) cores | R3: Tot # of Active cores | S3: x86 to z Active Core ratio | T3: Tot # of Active cores no DR | U3: x86 to z Core ratio no DR | V3: Tot # of cores | W3: x86 to z Core ratio
A4: x86 | B4: 10 | C4: 20 | D4: =ROUNDUP($C$2/$C4,0) -> 400 | E4: =IF(E2*D2>D4,D4,E2*D2) -> 80 | F4: =D4+E4 -> 480 | H4: 0.5 | I4: =ROUNDUP($F4*H4,0) -> 240 | J4: =H4 -> 0.5 | K4: =ROUNDUP($F4*J4,0) -> 240 | L4: 1 | M4: =ROUNDUP($F4*L4,0) -> 480 | N4: 1 | O4: =ROUNDUP(($F4+M4)*N4,0) -> 960 | R4: =F4+I4+K4+M4+O4 -> 2400 | S4: =R$4/R5 -> 20 | T4: =F4+I4+K4+M4 -> 1440 | U4: =T$4/T5 -> 12 | V4: =R4 -> 2400 | W4: =V$4/V5 -> 12
A5: LinuxONE | B5: 1 | C5: =$C$4*B4 -> 200 | D5: =ROUNDUP($C$2/$C5,0) -> 40 | F5: =D5+E5 -> 40 | H5: =H4 -> 0.5 | I5: =ROUNDUP($F5*H5,0) -> 20 | J5: =J4 -> 0.5 | K5: =ROUNDUP($F5*J5,0) -> 20 | L5: 1 | M5: =ROUNDUP($F5*L5,0) -> 40 | P5: =F5+M5 -> 80 | R5: =F5+I5+K5+M5+O5 -> 120 | T5: =F5+I5+K5+M5 -> 120 | V5: =R5+P5 -> 200
L6: * most customers would have exact replica of Prod
A7: Sizing Disclaimer:
A8: Calculation of required cores for a real workload requires sophisticated analysis.
A9: In order to make a simple and realistic sizing, for this exercise a simplified approach is used considering the Typical core ratio.
A10: The typical core ratio take into account:
A11: Architecture, GHz & utilization, VM & Hypervisor effect, System Overhead, Networking co-location effect, Sysplex, etc.
A12: Although these data will change slightly depending the server model used, these data averages are proved by many real workloads and documented also on papers such as those reported in the references.
A13: Reference: A. Micarelli, S. Proietti Conti, "Why Application Requirements Should Drive the Choice of your Infrastructure", 2021 IBM Corporation web published paper
A14: Download at: | B14: https://www.ibm.com/downloads/cas/2VVYYVNP
A16: Legend:
B17: Input field
B18: Optional input
B19: Suggested input (reccomended not change)
B20: Calculated values
B21: Calculated values highlighted (Very Important)
B22: Calculated values highlighted (Important)
B23: Constant

Sheet x86 TCO
A1: Small Size Enterprise | R1: Acquisition Cost | W1: Maintenance/ Operating Cost | AB1: TOTALS
A2: Typically x86 workload | R2: 1 | S2: 2 | T2: 3 | U2: 4 | V2: 5 | W2: 1 | X2: 2 | Y2: 3 | Z2: 4 | AA2: 5
A3: Hardware
A4: Server Model | C4: Acquisition Cost | D4: Maintenance/ Operating Cost | E4: Starting Year of Maint | F4: Discount % | G4: # of Cores per Server | H4: # of Sockets | I4: # of Cores per socket | J4: # of "boxes" per Rack | L4: kW
A5: {=INDEX(A6:A16,$B$5)} -> Rack HPE w Xeon Gold 6230 20C 2.10GHz (2 Chips, 40 Cores) | B5: =MATCH("S",B6:B16) -> 6 | C5: {=INDEX(C6:C16,$B$5)} -> 8000 | D5: {=INDEX(D6:D16,$B$5)} -> 1600 | E5: {=INDEX(E6:E16,$B$5)} -> 4 | F5: {=INDEX(F6:F16,$B$5)} -> 0 | G5: {=INDEX(G6:G16,$B$5)} -> 40 | H5: {=INDEX(H6:H16,$B$5)} -> 2 | I5: {=INDEX(I6:I16,$B$5)} -> 20 | J5: {=INDEX(J6:J16,$B$5)} -> 15 | L5: {=INDEX(L6:L16,$B$5)} -> 1.6
A6: Rack server w Xeon Gold 6244 8C 3.60GHz (2 Chips, 16 Cores) | B6: 0 | C6: 8000 | D6: =C6*0.2 -> 1600 | E6: 4 | F6: 0.3 | G6: =H6*I6 -> 16 | H6: 2 | I6: 8 | J6: 30 | L6: 0.5
A7: Rack server w Xeon Gold 5115 10C 2.40GHz (2 Chips, 20 Cores) | B7: 0 | C7: 10000 | D7: =C7*0.2 -> 2000 | E7: 4 | F7: 0.3 | G7: =H7*I7 -> 20 | H7: 2 | I7: 10 | J7: 30 | L7: 0.6
A8: Rack server w Xeon Gold 6146 12C 3.20GHz (2 Chips, 24 Cores) | B8: 0 | C8: 12000 | D8: =C8*0.2 -> 2400 | E8: 4 | F8: 0.3 | G8: =H8*I8 -> 24 | H8: 2 | I8: 12 | J8: 15 | L8: 1.2
A9: Rack server w Xeon Gold 6146 12C 3.20GHz (4 Chips, 48 Cores) | B9: 0 | C9: 24000 | D9: =C9*0.2 -> 4800 | E9: 4 | F9: 0.3 | G9: =H9*I9 -> 48 | H9: 4 | I9: 12 | J9: 15 | L9: 1.2
A10: =Data!A5 -> Rack DELL w Xeon Gold 5220 18C 2.20GHz (4 Chips, 72 Cores) | B10: 0 | C10: =Data!B5 -> 20800 | D10: =Data!C5 -> 4160 | E10: =Data!D5 -> 4 | F10: =Data!E5 -> 0.37 | G10: =H10*I10 -> 72 | H10: =Data!G5 -> 4 | I10: =Data!H5 -> 18 | J10: =Data!I5 -> 10 | L10: =Data!J5 -> 1.1
A11: =Data!A6 -> Rack HPE w Xeon Gold 6230 20C 2.10GHz (2 Chips, 40 Cores) | B11: S | C11: =Data!B6 -> 8000 | D11: =Data!C6 -> 1600 | E11: =Data!D6 -> 4 | F11: =Data!E6 -> 0 | G11: =H11*I11 -> 40 | H11: =Data!G6 -> 2 | I11: =Data!H6 -> 20 | J11: =Data!I6 -> 15 | L11: =Data!J6 -> 1.6
B12: 0 | G12: =H12*I12 -> 0
B13: 0 | G13: =H13*I13 -> 0
B14: 0 | G14: =H14*I14 -> 0
B15: 0 | G15: =H15*I15 -> 0
B16: 0 | G16: =H16*I16 -> 0
A18: Environment being investigated | C18: # of Cores for bare workload | D18: % of Cores vs bare workload | E18: Allocated Cores | F18: cores per Server | G18: Allocated Servers | H18: Tot cores available | I18: Spare Cores | J18: % of spare cores | K18: Allocated Sockets | O18: # of Server | P18: # of Sockets | Q18: # of Cores | R18: 1 | S18: 2 | T18: 3 | U18: 4 | V18: 5 | W18: 1 | X18: 2 | Y18: 3 | Z18: 4 | AA18: 5 | AB18: TOT
A19: Prod | C19: =sizing!D4 -> 400 | D19: see sizing | E19: =sizing!F4 -> 480 | F19: =$G$5 -> 40 | G19: =ROUNDUP(E19/F19,0) -> 12 | H19: =F19*G19 -> 480 | I19: =H19-E19 -> 0 | J19: =I19/H19 -> 0 | K19: =ROUNDUP(E19/$I$5,0) -> 24 | N19: Prod | O19: =G19 -> 12 | P19: =K19 -> 24 | Q19: =E19 -> 480 | R19: =$O19*$C$5*(1-$F$5) -> 96000 | W19: =IF(W$18<$E$5,0,$O19*$D$5)*(1-$F$5) -> 0 | X19: =IF(X$18<$E$5,0,$O19*$D$5)*(1-$F$5) -> 0 | Y19: =IF(Y$18<$E$5,0,$O19*$D$5)*(1-$F$5) -> 0 | Z19: =IF(Z$18<$E$5,0,$O19*$D$5)*(1-$F$5) -> 19200 | AA19: =IF(AA$18<$E$5,0,$O19*$D$5)*(1-$F$5) -> 19200 | AB19: =SUM(R19:AA19) -> 134400 | AC19: Prod
A20: Dev | D20: =sizing!H4 -> 0.5 | E20: =sizing!I4 -> 240 | F20: =$G$5 -> 40 | G20: =ROUNDUP(E20/F20,0) -> 6 | H20: =F20*G20 -> 240 | I20: =H20-E20 -> 0 | J20: =I20/H20 -> 0 | K20: =ROUNDUP(E20/$I$5,0) -> 12 | N20: Dev | O20: =G20 -> 6 | P20: =K20 -> 12 | Q20: =E20 -> 240 | R20: =$O20*$C$5*(1-$F$5) -> 48000 | W20: =IF(W$18<$E$5,0,$O20*$D$5)*(1-$F$5) -> 0 | X20: =IF(X$18<$E$5,0,$O20*$D$5)*(1-$F$5) -> 0 | Y20: =IF(Y$18<$E$5,0,$O20*$D$5)*(1-$F$5) -> 0 | Z20: =IF(Z$18<$E$5,0,$O20*$D$5)*(1-$F$5) -> 9600 | AA20: =IF(AA$18<$E$5,0,$O20*$D$5)*(1-$F$5) -> 9600 | AB20: =SUM(R20:AA20) -> 67200 | AC20: Dev
A21: Test | D21: =sizing!J4 -> 0.5 | E21: =sizing!K4 -> 240 | F21: =$G$5 -> 40 | G21: =ROUNDUP(E21/F21,0) -> 6 | H21: =F21*G21 -> 240 | I21: =H21-E21 -> 0 | J21: =I21/H21 -> 0 | K21: =ROUNDUP(E21/$I$5,0) -> 12 | N21: Test | O21: =G21 -> 6 | P21: =K21 -> 12 | Q21: =E21 -> 240 | R21: =$O21*$C$5*(1-$F$5) -> 48000 | W21: =IF(W$18<$E$5,0,$O21*$D$5)*(1-$F$5) -> 0 | X21: =IF(X$18<$E$5,0,$O21*$D$5)*(1-$F$5) -> 0 | Y21: =IF(Y$18<$E$5,0,$O21*$D$5)*(1-$F$5) -> 0 | Z21: =IF(Z$18<$E$5,0,$O21*$D$5)*(1-$F$5) -> 9600 | AA21: =IF(AA$18<$E$5,0,$O21*$D$5)*(1-$F$5) -> 9600 | AB21: =SUM(R21:AA21) -> 67200 | AC21: Test
A22: PreProd | D22: =sizing!L4 -> 1 | E22: =sizing!M4 -> 480 | F22: =$G$5 -> 40 | G22: =ROUNDUP(E22/F22,0) -> 12 | H22: =F22*G22 -> 480 | I22: =H22-E22 -> 0 | J22: =I22/H22 -> 0 | K22: =ROUNDUP(E22/$I$5,0) -> 24 | N22: PreProd | O22: =G22 -> 12 | P22: =K22 -> 24 | Q22: =E22 -> 480 | R22: =$O22*$C$5*(1-$F$5) -> 96000 | W22: =IF(W$18<$E$5,0,$O22*$D$5)*(1-$F$5) -> 0 | X22: =IF(X$18<$E$5,0,$O22*$D$5)*(1-$F$5) -> 0 | Y22: =IF(Y$18<$E$5,0,$O22*$D$5)*(1-$F$5) -> 0 | Z22: =IF(Z$18<$E$5,0,$O22*$D$5)*(1-$F$5) -> 19200 | AA22: =IF(AA$18<$E$5,0,$O22*$D$5)*(1-$F$5) -> 19200 | AB22: =SUM(R22:AA22) -> 134400 | AC22: QA
A23: DR | D23: =sizing!N4 -> 1 | E23: =sizing!O4 -> 960 | F23: =$G$5 -> 40 | G23: =G19+G22 -> 24 | H23: =F23*G23 -> 960 | I23: =H23-E23 -> 0 | J23: =I23/H23 -> 0 | K23: =ROUNDUP(E23/$I$5,0) -> 48 | N23: DR | O23: =G23 -> 24 | P23: =K23 -> 48 | Q23: =E23 -> 960 | R23: =$O23*$C$5*(1-$F$5) -> 192000 | W23: =IF(W$18<$E$5,0,$O23*$D$5)*(1-$F$5) -> 0 | X23: =IF(X$18<$E$5,0,$O23*$D$5)*(1-$F$5) -> 0 | Y23: =IF(Y$18<$E$5,0,$O23*$D$5)*(1-$F$5) -> 0 | Z23: =IF(Z$18<$E$5,0,$O23*$D$5)*(1-$F$5) -> 38400 | AA23: =IF(AA$18<$E$5,0,$O23*$D$5)*(1-$F$5) -> 38400 | AB23: =SUM(R23:AA23) -> 268800 | AC23: DR
A24: TOT | E24: =SUM(E19:E23) -> 2400 | G24: =SUM(G19:G23) -> 60 | H24: =SUM(H19:H23) -> 2400 | I24: =SUM(I19:I23) -> 0 | J24: =I24/H24 -> 0 | K24: =SUM(K19:K23) -> 120 | O24: =SUM(O19:O23) -> 60 | P24: =SUM(P19:P23) -> 120 | Q24: =SUM(Q19:Q23) -> 2400 | R24: =SUM(R19:R23) -> 480000 | S24: =SUM(S19:S23) -> 0 | T24: =SUM(T19:T23) -> 0 | U24: =SUM(U19:U23) -> 0 | V24: =SUM(V19:V23) -> 0 | ... AB24: =SUM(AB19:AB23) -> 672000 | AC24: TOT
O25: # of Server | P25: # of Sockets | Q25: # of Cores
A26: Software Stack
A27: Production | C27: Acquisition/ Capital Cost | D27: Maintenance/ Operating Cost | E27: Starting Year of yearly charges | F27: Discount % | G27: Unit of Measure | H27: Measured by | I27: conversion factor | J27: server | K27: socket | L27: core | O27: count | P27: Unit of Measure | Q27: Units | R27: 1 | S27: 2 | T27: 3 | U27: 4 | V27: 5 | W27: 1 | X27: 2 | Y27: 3 | Z27: 4 | AA27: 5 | AB27: TOT
A28: OS | D28: 2000 | E28: 1 | F28: 0.2 | G28: socket | H28: socket | I28: 1 | J28: =$O$19 -> 12 | K28: =$P$19 -> 24 | L28: =$Q$19 -> 480 | O28: =_xlfn.XLOOKUP($H28,$J$27:$L$27,$J28:$L28) -> 24 | P28: socket | Q28: =I28*O28 -> 24 | R28: =$Q28*$C28*(1-$F28) -> 0 | W28: =IF(W$18<$E28,0,$Q28*$D28)*(1-$F28) -> 38400 | X28: =IF(X$18<$E28,0,$Q28*$D28)*(1-$F28) -> 38400 | Y28: =IF(Y$18<$E28,0,$Q28*$D28)*(1-$F28) -> 38400 | Z28: =IF(Z$18<$E28,0,$Q28*$D28)*(1-$F28) -> 38400 | AA28: =IF(AA$18<$E28,0,$Q28*$D28)*(1-$F28) -> 38400 | AB28: =SUM(R28:AA28) -> 192000
A29: VM | C29: 5000 | D29: =C29*0.2 -> 1000 | E29: 2 | F29: 0.2 | G29: socket | H29: socket | I29: 1 | J29: =J28 -> 12 | K29: =K28 -> 24 | L29: =L28 -> 480 | O29: =_xlfn.XLOOKUP($H29,$J$27:$L$27,$J29:$L29) -> 24 | P29: socket | Q29: =I29*O29 -> 24 | R29: =$Q29*$C29*(1-$F29) -> 96000 | W29: =IF(W$18<$E29,0,$Q29*$D29)*(1-$F29) -> 0 | X29: =IF(X$18<$E29,0,$Q29*$D29)*(1-$F29) -> 19200 | Y29: =IF(Y$18<$E29,0,$Q29*$D29)*(1-$F29) -> 19200 | Z29: =IF(Z$18<$E29,0,$Q29*$D29)*(1-$F29) -> 19200 | AA29: =IF(AA$18<$E29,0,$Q29*$D29)*(1-$F29) -> 19200 | AB29: =SUM(R29:AA29) -> 172800
A30: Application Server | C30: =Data!B12 -> 46.82 | D30: =Data!C12 -> 9.36 | E30: =Data!D12 -> 2 | F30: 0.75 | G30: =Data!E12 -> PVU | H30: =Data!F12 -> core | I30: 70 | J30: =J29 -> 12 | K30: =K29 -> 24 | L30: =L29 -> 480 | O30: =_xlfn.XLOOKUP($H30,$J$27:$L$27,$J30:$L30) -> 480 | P30: PVU | Q30: =I30*O30 -> 33600 | R30: =$Q30*$C30*(1-$F30) -> 393288 | W30: =IF(W$18<$E30,0,$Q30*$D30)*(1-$F30) -> 0 | X30: =IF(X$18<$E30,0,$Q30*$D30)*(1-$F30) -> 78624 | Y30: =IF(Y$18<$E30,0,$Q30*$D30)*(1-$F30) -> 78624 | Z30: =IF(Z$18<$E30,0,$Q30*$D30)*(1-$F30) -> 78624 | AA30: =IF(AA$18<$E30,0,$Q30*$D30)*(1-$F30) -> 78624 | AB30: =SUM(R30:AA30) -> 707784
A31: DB | C31: =Data!B25 -> 0 | D31: =Data!C25 -> 8500 | E31: =Data!D25 -> 1 | F31: 0 | G31: =Data!E25 -> server | H31: =Data!F25 -> server | I31: 1 | J31: =J30 -> 12 | K31: =K30 -> 24 | L31: =L30 -> 480 | O31: =_xlfn.XLOOKUP($H31,$J$27:$L$27,$J31:$L31) -> 12 | P31: core | Q31: =I31*O31 -> 12 | R31: =$Q31*$C31*(1-$F31) -> 0 | W31: =IF(W$18<$E31,0,$Q31*$D31)*(1-$F31) -> 102000 | X31: =IF(X$18<$E31,0,$Q31*$D31)*(1-$F31) -> 102000 | Y31: =IF(Y$18<$E31,0,$Q31*$D31)*(1-$F31) -> 102000 | Z31: =IF(Z$18<$E31,0,$Q31*$D31)*(1-$F31) -> 102000 | AA31: =IF(AA$18<$E31,0,$Q31*$D31)*(1-$F31) -> 102000 | AB31: =SUM(R31:AA31) -> 510000
A32: Data Replication Tools | D32: 3000 | E32: 1 | F32: 0.75 | G32: core | H32: core | I32: 0.5 | J32: =J31 -> 12 | K32: =K31 -> 24 | L32: =L31 -> 480 | O32: =_xlfn.XLOOKUP($H32,$J$27:$L$27,$J32:$L32) -> 480 | P32: core | Q32: =I32*O32 -> 240 | R32: =$Q32*$C32*(1-$F32) -> 0 | W32: =IF(W$18<$E32,0,$Q32*$D32)*(1-$F32) -> 180000 | X32: =IF(X$18<$E32,0,$Q32*$D32)*(1-$F32) -> 180000 | Y32: =IF(Y$18<$E32,0,$Q32*$D32)*(1-$F32) -> 180000 | Z32: =IF(Z$18<$E32,0,$Q32*$D32)*(1-$F32) -> 180000 | AA32: =IF(AA$18<$E32,0,$Q32*$D32)*(1-$F32) -> 180000 | AB32: =SUM(R32:AA32) -> 900000
A33: Monitoring Tools | C33: 5000 | D33: =C33*0.2 -> 1000 | E33: 2 | F33: 0.4 | G33: server | H33: server | I33: 1 | J33: =J32 -> 12 | K33: =K32 -> 24 | L33: =L32 -> 480 | O33: =_xlfn.XLOOKUP($H33,$J$27:$L$27,$J33:$L33) -> 12 | P33: server | Q33: =I33*O33 -> 12 | R33: =$Q33*$C33*(1-$F33) -> 36000 | W33: =IF(W$18<$E33,0,$Q33*$D33)*(1-$F33) -> 0 | X33: =IF(X$18<$E33,0,$Q33*$D33)*(1-$F33) -> 7200 | Y33: =IF(Y$18<$E33,0,$Q33*$D33)*(1-$F33) -> 7200 | Z33: =IF(Z$18<$E33,0,$Q33*$D33)*(1-$F33) -> 7200 | AA33: =IF(AA$18<$E33,0,$Q33*$D33)*(1-$F33) -> 7200 | AB33: =SUM(R33:AA33) -> 64800
A34: Security Tools | C34: 5000 | D34: =C34*0.2 -> 1000 | E34: 2 | F34: 0.4 | G34: server | H34: server | I34: 1 | J34: =J33 -> 12 | K34: =K33 -> 24 | L34: =L33 -> 480 | O34: =_xlfn.XLOOKUP($H34,$J$27:$L$27,$J34:$L34) -> 12 | P34: server | Q34: =I34*O34 -> 12 | R34: =$Q34*$C34*(1-$F34) -> 36000 | W34: =IF(W$18<$E34,0,$Q34*$D34)*(1-$F34) -> 0 | X34: =IF(X$18<$E34,0,$Q34*$D34)*(1-$F34) -> 7200 | Y34: =IF(Y$18<$E34,0,$Q34*$D34)*(1-$F34) -> 7200 | Z34: =IF(Z$18<$E34,0,$Q34*$D34)*(1-$F34) -> 7200 | AA34: =IF(AA$18<$E34,0,$Q34*$D34)*(1-$F34) -> 7200 | AB34: =SUM(R34:AA34) -> 64800
Q35: PROD | R35: =SUM(R28:R34) -> 561288 | S35: =SUM(S28:S34) -> 0 | T35: =SUM(T28:T34) -> 0 | U35: =SUM(U28:U34) -> 0 | V35: =SUM(V28:V34) -> 0 | W35: =SUM(W28:W34) -> 320400 | X35: =SUM(X28:X34) -> 432624 | Y35: =SUM(Y28:Y34) -> 432624 | ... AB35: =SUM(AB28:AB34) -> 2612184
A37: Dev | C37: Acquisition/ Capital Cost | D37: Maintenance/ Operating Cost | E37: =E27 -> Starting Year of yearly charges | F37: Discount % | G37: Unit of Measure | H37: Measured by | I37: conversion factor | J37: server | K37: socket | L37: core | O37: count | P37: Unit of Measure | Q37: Units | R37: 1 | S37: 2 | T37: 3 | U37: 4 | V37: 5 | W37: 1 | X37: 2 | Y37: 3 | Z37: 4 | AA37: 5 | AB37: TOT
A38: =A28 -> OS | C38: =C28 -> 0 | D38: =D28 -> 2000 | E38: =E28 -> 1 | F38: =F28 -> 0.2 | G38: =G28 -> socket | H38: =H28 -> socket | I38: =I28 -> 1 | J38: =$O$20 -> 6 | K38: =$P$20 -> 12 | L38: =$Q$20 -> 240 | O38: =_xlfn.XLOOKUP($H38,$J$27:$L$27,$J38:$L38) -> 12 | P38: socket | Q38: =I38*O38 -> 12 | R38: =$Q38*$C38*(1-$F38) -> 0 | W38: =IF(W$18<$E38,0,$Q38*$D38)*(1-$F38) -> 19200 | X38: =IF(X$18<$E38,0,$Q38*$D38)*(1-$F38) -> 19200 | Y38: =IF(Y$18<$E38,0,$Q38*$D38)*(1-$F38) -> 19200 | Z38: =IF(Z$18<$E38,0,$Q38*$D38)*(1-$F38) -> 19200 | AA38: =IF(AA$18<$E38,0,$Q38*$D38)*(1-$F38) -> 19200 | AB38: =SUM(R38:AA38) -> 96000
A39: =A29 -> VM | C39: =C29 -> 5000 | D39: =D29 -> 1000 | E39: =E29 -> 2 | F39: =F29 -> 0.2 | G39: =G29 -> socket | H39: =H29 -> socket | I39: =I29 -> 1 | J39: =J38 -> 6 | K39: =K38 -> 12 | L39: =L38 -> 240 | O39: =_xlfn.XLOOKUP($H39,$J$27:$L$27,$J39:$L39) -> 12 | P39: socket | Q39: =I39*O39 -> 12 | R39: =$Q39*$C39*(1-$F39) -> 48000 | W39: =IF(W$18<$E39,0,$Q39*$D39)*(1-$F39) -> 0 | X39: =IF(X$18<$E39,0,$Q39*$D39)*(1-$F39) -> 9600 | Y39: =IF(Y$18<$E39,0,$Q39*$D39)*(1-$F39) -> 9600 | Z39: =IF(Z$18<$E39,0,$Q39*$D39)*(1-$F39) -> 9600 | AA39: =IF(AA$18<$E39,0,$Q39*$D39)*(1-$F39) -> 9600 | AB39: =SUM(R39:AA39) -> 86400
A40: =A30 -> Application Server | C40: =C30 -> 46.82 | D40: =D30 -> 9.36 | E40: =E30 -> 2 | F40: =F30 -> 0.75 | G40: =G30 -> PVU | H40: =H30 -> core | I40: =I30 -> 70 | J40: =J39 -> 6 | K40: =K39 -> 12 | L40: =L39 -> 240 | O40: =_xlfn.XLOOKUP($H40,$J$27:$L$27,$J40:$L40) -> 240 | P40: PVU | Q40: =I40*O40 -> 16800 | R40: =$Q40*$C40*(1-$F40) -> 196644 | W40: =IF(W$18<$E40,0,$Q40*$D40)*(1-$F40) -> 0 | X40: =IF(X$18<$E40,0,$Q40*$D40)*(1-$F40) -> 39312 | Y40: =IF(Y$18<$E40,0,$Q40*$D40)*(1-$F40) -> 39312 | Z40: =IF(Z$18<$E40,0,$Q40*$D40)*(1-$F40) -> 39312 | AA40: =IF(AA$18<$E40,0,$Q40*$D40)*(1-$F40) -> 39312 | AB40: =SUM(R40:AA40) -> 353892
A41: =A31 -> DB | C41: =C31 -> 0 | D41: =D31 -> 8500 | E41: =E31 -> 1 | F41: =F31 -> 0 | G41: =G31 -> server | H41: =H31 -> server | I41: =I31 -> 1 | J41: =J40 -> 6 | K41: =K40 -> 12 | L41: =L40 -> 240 | O41: =_xlfn.XLOOKUP($H41,$J$27:$L$27,$J41:$L41) -> 6 | P41: core | Q41: =I41*O41 -> 6 | R41: =$Q41*$C41*(1-$F41) -> 0 | W41: =IF(W$18<$E41,0,$Q41*$D41)*(1-$F41) -> 51000 | X41: =IF(X$18<$E41,0,$Q41*$D41)*(1-$F41) -> 51000 | Y41: =IF(Y$18<$E41,0,$Q41*$D41)*(1-$F41) -> 51000 | Z41: =IF(Z$18<$E41,0,$Q41*$D41)*(1-$F41) -> 51000 | AA41: =IF(AA$18<$E41,0,$Q41*$D41)*(1-$F41) -> 51000 | AB41: =SUM(R41:AA41) -> 255000
A42: =A32 -> Data Replication Tools | C42: =C32 -> 0 | D42: =D32 -> 3000 | E42: =E32 -> 1 | F42: =F32 -> 0.75 | G42: =G32 -> core | H42: =H32 -> core | I42: =I32 -> 0.5 | J42: =J41 -> 6 | K42: =K41 -> 12 | L42: =L41 -> 240 | O42: =_xlfn.XLOOKUP($H42,$J$27:$L$27,$J42:$L42) -> 240 | P42: core | Q42: =I42*O42 -> 120 | R42: =$Q42*$C42*(1-$F42) -> 0 | W42: =IF(W$18<$E42,0,$Q42*$D42)*(1-$F42) -> 90000 | X42: =IF(X$18<$E42,0,$Q42*$D42)*(1-$F42) -> 90000 | Y42: =IF(Y$18<$E42,0,$Q42*$D42)*(1-$F42) -> 90000 | Z42: =IF(Z$18<$E42,0,$Q42*$D42)*(1-$F42) -> 90000 | AA42: =IF(AA$18<$E42,0,$Q42*$D42)*(1-$F42) -> 90000 | AB42: =SUM(R42:AA42) -> 450000
...

Sheet LinuxONE TCO
A1: Enterprise Grade Linux Environment | R1: Acquisition/Capital Cost | W1: Maintenance/ Operating Cost | AB1: TOTALS
A2: Typically LinuxONE | R2: 1 | S2: 2 | T2: 3 | U2: 4 | V2: 5 | W2: 1 | X2: 2 | Y2: 3 | Z2: 4 | AA2: 5
A3: Hardware
A4: Linux ONE | C4: Acquisition Cost | D4: Included cores | E4: core cost | F4: CBU Cost | G4: Discount % | H4: # of Cores per Server | I4: Maintenance/ Operating Cost | J4: Starting Year of Maint | K4: kW | O4: SW Incl | P4: SW incl | Q4: SW incl | R4: SW incl
A5: Simplicistic model to build a price example | C5: 600000 | D5: 6 | E5: 50000 | F5: 5000 | G5: 0.3 | H5: 190 | I5: 0.1 | J5: 4 | K5: 15 | O5: OS | P5: VM | Q5: Admin | R5: Management
A6: This is an estimate based on this web page: | C6: https://www.ibm.com/it-infrastructure/resources/tools/linuxone-tco-calculator/
A8: Simplicistic architecture considering always 2 LinuxONE servers, each one in a different site for HA & DR
C9: # of Cores (core) for bare workload | D9: % of Cores vs bare workload | E9: Allocated Cores | F9: Site 1 core | G9: Site 2 core | H9: Site 1 CBU | I9: Site 2 CBU | K9: Allocation % | O9: # of Server | P9: # of Sockets | Q9: # of Cores | R9: 1 | S9: 2 | T9: 3 | U9: 4 | V9: 5 | W9: 1 | X9: 2 | Y9: 3 | Z9: 4 | AA9: 5 | AB9: TOT
A10: Prod | C10: =sizing!D5 -> 40 | D10: see sizing | E10: =sizing!F5 -> 40 | F10: =ROUNDUP(E10,0) -> 40 | I10: =F10 -> 40 | J10: Prod | K10: =$E10/$E$15 -> 0.33333333 | N10: Prod | O10: =K10*2 -> 0.66666667 | P10: =Q10 -> 40 | Q10: =SUM(F10:G10) -> 40 | R10: =$K10*($F$16+$G$16)*(1-$G$5) -> 1540000 | W10: =IF(W$9<$J$5,0,$R10*$I$5) -> 0 | X10: =IF(X$9<$J$5,0,$R10*$I$5) -> 0 | Y10: =IF(Y$9<$J$5,0,$R10*$I$5) -> 0 | Z10: =IF(Z$9<$J$5,0,$R10*$I$5) -> 154000 | AA10: =IF(AA$9<$J$5,0,$R10*$I$5) -> 154000 | AB10: =SUM(R10:AA10) -> 1848000 | AC10: Prod
A11: Dev | D11: =sizing!H5 -> 0.5 | E11: =ROUNDUP($C$10*D11,0) -> 20 | F11: =E11 -> 20 | G11: =E11-F11 -> 0 | J11: Dev | K11: =$E11/$E$15 -> 0.16666667 | N11: Dev | O11: =K11*2 -> 0.33333333 | P11: =Q11 -> 20 | Q11: =SUM(F11:G11) -> 20 | R11: =$K11*($F$16+$G$16)*(1-$G$5) -> 770000 | W11: =IF(W$9<$J$5,0,$R11*$I$5) -> 0 | X11: =IF(X$9<$J$5,0,$R11*$I$5) -> 0 | Y11: =IF(Y$9<$J$5,0,$R11*$I$5) -> 0 | Z11: =IF(Z$9<$J$5,0,$R11*$I$5) -> 77000 | AA11: =IF(AA$9<$J$5,0,$R11*$I$5) -> 77000 | AB11: =SUM(R11:AA11) -> 924000 | AC11: Dev
A12: Test | D12: =sizing!J5 -> 0.5 | E12: =ROUNDUP($C$10*D12,0) -> 20 | F12: =E12-G12 -> 0 | G12: =E12 -> 20 | J12: Test | K12: =$E12/$E$15 -> 0.16666667 | N12: Test | O12: =K12*2 -> 0.33333333 | P12: =Q12 -> 20 | Q12: =SUM(F12:G12) -> 20 | R12: =$K12*($F$16+$G$16)*(1-$G$5) -> 770000 | W12: =IF(W$9<$J$5,0,$R12*$I$5) -> 0 | X12: =IF(X$9<$J$5,0,$R12*$I$5) -> 0 | Y12: =IF(Y$9<$J$5,0,$R12*$I$5) -> 0 | Z12: =IF(Z$9<$J$5,0,$R12*$I$5) -> 77000 | AA12: =IF(AA$9<$J$5,0,$R12*$I$5) -> 77000 | AB12: =SUM(R12:AA12) -> 924000 | AC12: Test
A13: PreProd | D13: =sizing!L5 -> 1 | E13: =ROUNDUP($C$10*D13,0) -> 40 | G13: =C10 -> 40 | H13: =G13 -> 40 | J13: QA | K13: =$E13/$E$15 -> 0.33333333 | N13: QA | O13: =K13*2 -> 0.66666667 | P13: =Q13 -> 40 | Q13: =SUM(F13:G13) -> 40 | R13: =$K13*($F$16+$G$16)*(1-$G$5) -> 1540000 | W13: =IF(W$9<$J$5,0,$R13*$I$5) -> 0 | X13: =IF(X$9<$J$5,0,$R13*$I$5) -> 0 | Y13: =IF(Y$9<$J$5,0,$R13*$I$5) -> 0 | Z13: =IF(Z$9<$J$5,0,$R13*$I$5) -> 154000 | AA13: =IF(AA$9<$J$5,0,$R13*$I$5) -> 154000 | AB13: =SUM(R13:AA13) -> 1848000 | AC13: QA
A14: DR | H14: =SUM(H10:H13) -> 40 | I14: =SUM(I10:I13) -> 40 | J14: DR | N14: DR | R14: =($H$16+$I$16)*(1-$G$5) -> 280000 | W14: =IF(W$9<$J$5,0,$R14*$I$5) -> 0 | X14: =IF(X$9<$J$5,0,$R14*$I$5) -> 0 | Y14: =IF(Y$9<$J$5,0,$R14*$I$5) -> 0 | Z14: =IF(Z$9<$J$5,0,$R14*$I$5) -> 28000 | AA14: =IF(AA$9<$J$5,0,$R14*$I$5) -> 28000 | AB14: =SUM(R14:AA14) -> 336000 | AC14: DR
A15: TOT | E15: =SUM(E10:E14) -> 120 | F15: =SUM(F10:F14) -> 60 | G15: =SUM(G10:G14) -> 60 | H15: =H14 -> 40 | I15: =I14 -> 40 | K15: =SUM(K10:K14) -> 1 | O15: =SUM(O10:O14) -> 2 | P15: =SUM(P10:P14) -> 120 | Q15: =SUM(Q10:Q14) -> 120 | R15: =SUM(R10:R14) -> 4900000 | S15: =SUM(S10:S14) -> 0 | T15: =SUM(T10:T14) -> 0 | U15: =SUM(U10:U14) -> 0 | V15: =SUM(V10:V14) -> 0 | ... AB15: =SUM(AB10:AB14) -> 5880000 | AC15: TOT
E16: Price per Site | F16: =IF($D$5<F15,((F15-$D$5)*$E$5+$C$5),$C$5) -> 3300000 | G16: =IF($D$5<G15,((G15-$D$5)*$E$5+$C$5),$C$5) -> 3300000 | H16: =($H$15*$F$5) -> 200000 | I16: =($I$15*$F$5) -> 200000 | O16: # of Server | P16: # of Sockets | Q16: # of Cores
A22: Software Stack
A23: Production | C23: Acquisition/ Capital Cost | D23: Maintenance/ Subscription | E23: Starting Year of Maint charges | F23: Discount % | G23: Unit of Measure | H23: Measured by | I23: conversion factor | J23: server | K23: socket | L23: core | O23: count | P23: Unit of Measure | Q23: Units | R23: 1 | S23: 2 | T23: 3 | U23: 4 | V23: 5 | W23: 1 | X23: 2 | Y23: 3 | Z23: 4 | AA23: 5 | AB23: TOT
A24: OS | D24: 6000 | E24: 1 | F24: 0.2 | G24: core | H24: core | I24: 1 | J24: =$O$10 -> 0.66666667 | K24: =$P$10 -> 40 | L24: =$Q$10 -> 40 | O24: =_xlfn.XLOOKUP($H24,$J$23:$L$23,$J24:$L24) -> 40 | P24: socket | Q24: =I24*O24 -> 40 | R24: =$Q24*$C24*(1-$F24) -> 0 | W24: =IF(W$9<$E24,0,$Q24*$D24)*(1-$F24) -> 192000 | X24: =IF(X$9<$E24,0,$Q24*$D24)*(1-$F24) -> 192000 | Y24: =IF(Y$9<$E24,0,$Q24*$D24)*(1-$F24) -> 192000 | Z24: =IF(Z$9<$E24,0,$Q24*$D24)*(1-$F24) -> 192000 | AA24: =IF(AA$9<$E24,0,$Q24*$D24)*(1-$F24) -> 192000 | AB24: =SUM(R24:AA24) -> 960000
A25: VM | E25: 2 | F25: 0.2 | G25: core | H25: core | I25: 1 | J25: =J24 -> 0.66666667 | K25: =K24 -> 40 | L25: =L24 -> 40 | O25: =_xlfn.XLOOKUP($H25,$J$23:$L$23,$J25:$L25) -> 40 | P25: socket | Q25: =I25*O25 -> 40 | R25: =$Q25*$C25*(1-$F25) -> 0 | W25: =IF(W$9<$E25,0,$Q25*$D25)*(1-$F25) -> 0 | X25: =IF(X$9<$E25,0,$Q25*$D25)*(1-$F25) -> 0 | Y25: =IF(Y$9<$E25,0,$Q25*$D25)*(1-$F25) -> 0 | Z25: =IF(Z$9<$E25,0,$Q25*$D25)*(1-$F25) -> 0 | AA25: =IF(AA$9<$E25,0,$Q25*$D25)*(1-$F25) -> 0 | AB25: =SUM(R25:AA25) -> 0
A26: Application Server | C26: =Data!B12 -> 46.82 | D26: =Data!C12 -> 9.36 | E26: =Data!D12 -> 2 | F26: 0.5 | G26: =Data!E12 -> PVU | H26: =Data!F12 -> core | I26: 120 | J26: =J25 -> 0.66666667 | K26: =K25 -> 40 | L26: =L25 -> 40 | O26: =_xlfn.XLOOKUP($H26,$J$23:$L$23,$J26:$L26) -> 40 | P26: PVU | Q26: =I26*O26 -> 4800 | R26: =$Q26*$C26*(1-$F26) -> 112368 | W26: =IF(W$9<$E26,0,$Q26*$D26)*(1-$F26) -> 0 | X26: =IF(X$9<$E26,0,$Q26*$D26)*(1-$F26) -> 22464 | Y26: =IF(Y$9<$E26,0,$Q26*$D26)*(1-$F26) -> 22464 | Z26: =IF(Z$9<$E26,0,$Q26*$D26)*(1-$F26) -> 22464 | AA26: =IF(AA$9<$E26,0,$Q26*$D26)*(1-$F26) -> 22464 | AB26: =SUM(R26:AA26) -> 202224
A27: DB | C27: =Data!B25 -> 0 | D27: =Data!C25 -> 8500 | E27: =Data!D25 -> 1 | F27: 0 | G27: =Data!E25 -> server | H27: =Data!F25 -> server | I27: 1 | J27: =J26 -> 0.66666667 | K27: =K26 -> 40 | L27: =L26 -> 40 | O27: =_xlfn.XLOOKUP($H27,$J$23:$L$23,$J27:$L27) -> 0.66666667 | P27: core | Q27: =I27*O27 -> 0.66666667 | R27: =$Q27*$C27*(1-$F27) -> 0 | W27: =IF(W$9<$E27,0,$Q27*$D27)*(1-$F27) -> 5666.6667 | X27: =IF(X$9<$E27,0,$Q27*$D27)*(1-$F27) -> 5666.6667 | Y27: =IF(Y$9<$E27,0,$Q27*$D27)*(1-$F27) -> 5666.6667 | Z27: =IF(Z$9<$E27,0,$Q27*$D27)*(1-$F27) -> 5666.6667 | AA27: =IF(AA$9<$E27,0,$Q27*$D27)*(1-$F27) -> 5666.6667 | AB27: =SUM(R27:AA27) -> 28333.333
A28: Data Replication Tools | D28: 3000 | E28: 1 | F28: 0.5 | G28: core | H28: core | I28: 1 | J28: =J27 -> 0.66666667 | K28: =K27 -> 40 | L28: =L27 -> 40 | O28: =_xlfn.XLOOKUP($H28,$J$23:$L$23,$J28:$L28) -> 40 | P28: core | Q28: =I28*O28 -> 40 | R28: =$Q28*$C28*(1-$F28) -> 0 | W28: =IF(W$9<$E28,0,$Q28*$D28)*(1-$F28) -> 60000 | X28: =IF(X$9<$E28,0,$Q28*$D28)*(1-$F28) -> 60000 | Y28: =IF(Y$9<$E28,0,$Q28*$D28)*(1-$F28) -> 60000 | Z28: =IF(Z$9<$E28,0,$Q28*$D28)*(1-$F28) -> 60000 | AA28: =IF(AA$9<$E28,0,$Q28*$D28)*(1-$F28) -> 60000 | AB28: =SUM(R28:AA28) -> 300000
A29: Monitoring Tools | C29: 5000 | D29: =C29*0.2 -> 1000 | E29: 2 | F29: 0.4 | G29: server | H29: server | I29: 1 | J29: =J28 -> 0.66666667 | K29: =K28 -> 40 | L29: =L28 -> 40 | O29: =_xlfn.XLOOKUP($H29,$J$23:$L$23,$J29:$L29) -> 0.66666667 | P29: server | Q29: =I29*O29 -> 0.66666667 | R29: =$Q29*$C29*(1-$F29) -> 2000 | W29: =IF(W$9<$E29,0,$Q29*$D29)*(1-$F29) -> 0 | X29: =IF(X$9<$E29,0,$Q29*$D29)*(1-$F29) -> 400 | Y29: =IF(Y$9<$E29,0,$Q29*$D29)*(1-$F29) -> 400 | Z29: =IF(Z$9<$E29,0,$Q29*$D29)*(1-$F29) -> 400 | AA29: =IF(AA$9<$E29,0,$Q29*$D29)*(1-$F29) -> 400 | AB29: =SUM(R29:AA29) -> 3600
A30: Security Tools | C30: 5000 | D30: =C30*0.2 -> 1000 | E30: 2 | F30: 0.4 | G30: server | H30: server | I30: 1 | J30: =J29 -> 0.66666667 | K30: =K29 -> 40 | L30: =L29 -> 40 | O30: =_xlfn.XLOOKUP($H30,$J$23:$L$23,$J30:$L30) -> 0.66666667 | P30: server | Q30: =I30*O30 -> 0.66666667 | R30: =$Q30*$C30*(1-$F30) -> 2000 | W30: =IF(W$9<$E30,0,$Q30*$D30)*(1-$F30) -> 0 | X30: =IF(X$9<$E30,0,$Q30*$D30)*(1-$F30) -> 400 | Y30: =IF(Y$9<$E30,0,$Q30*$D30)*(1-$F30) -> 400 | Z30: =IF(Z$9<$E30,0,$Q30*$D30)*(1-$F30) -> 400 | AA30: =IF(AA$9<$E30,0,$Q30*$D30)*(1-$F30) -> 400 | AB30: =SUM(R30:AA30) -> 3600
Q31: PROD | R31: =SUM(R24:R30) -> 116368 | S31: =SUM(S24:S30) -> 0 | T31: =SUM(T24:T30) -> 0 | U31: =SUM(U24:U30) -> 0 | V31: =SUM(V24:V30) -> 0 | W31: =SUM(W24:W30) -> 257666.67 | X31: =SUM(X24:X30) -> 280930.67 | Y31: =SUM(Y24:Y30) -> 280930.67 | ... AB31: =SUM(AB24:AB30) -> 1497757.3
A33: Dev | C33: =C23 -> Acquisition/ Capital Cost | D33: =D23 -> Maintenance/ Subscription | E33: Starting Year of Maint charges | F33: Discount % | G33: Unit of Measure | H33: Measured by | I33: conversion factor | J33: server | K33: socket | L33: core | O33: count | P33: Unit of Measure | Q33: Units | R33: 1 | S33: 2 | T33: 3 | U33: 4 | V33: 5 | W33: 1 | X33: 2 | Y33: 3 | Z33: 4 | AA33: 5 | AB33: TOT
A34: =A24 -> OS | C34: =C24 -> 0 | D34: =D24 -> 6000 | E34: =E24 -> 1 | F34: =F24 -> 0.2 | G34: =G24 -> core | H34: =H24 -> core | I34: =I24 -> 1 | J34: =$O$11 -> 0.33333333 | K34: =$P$11 -> 20 | L34: =$Q$11 -> 20 | O34: =_xlfn.XLOOKUP($H34,$J$23:$L$23,$J34:$L34) -> 20 | P34: socket | Q34: =I34*O34 -> 20 | R34: =$Q34*$C34*(1-$F34) -> 0 | W34: =IF(W$9<$E34,0,$Q34*$D34)*(1-$F34) -> 96000 | X34: =IF(X$9<$E34,0,$Q34*$D34)*(1-$F34) -> 96000 | Y34: =IF(Y$9<$E34,0,$Q34*$D34)*(1-$F34) -> 96000 | Z34: =IF(Z$9<$E34,0,$Q34*$D34)*(1-$F34) -> 96000 | AA34: =IF(AA$9<$E34,0,$Q34*$D34)*(1-$F34) -> 96000 | AB34: =SUM(R34:AA34) -> 480000
A35: =A25 -> VM | C35: =C25 -> 0 | D35: =D25 -> 0 | E35: =E25 -> 2 | F35: =F25 -> 0.2 | G35: =G25 -> core | H35: =H25 -> core | I35: =I25 -> 1 | J35: =J34 -> 0.33333333 | K35: =K34 -> 20 | L35: =L34 -> 20 | O35: =_xlfn.XLOOKUP($H35,$J$23:$L$23,$J35:$L35) -> 20 | P35: socket | Q35: =I35*O35 -> 20 | R35: =$Q35*$C35*(1-$F35) -> 0 | W35: =IF(W$9<$E35,0,$Q35*$D35)*(1-$F35) -> 0 | X35: =IF(X$9<$E35,0,$Q35*$D35)*(1-$F35) -> 0 | Y35: =IF(Y$9<$E35,0,$Q35*$D35)*(1-$F35) -> 0 | Z35: =IF(Z$9<$E35,0,$Q35*$D35)*(1-$F35) -> 0 | AA35: =IF(AA$9<$E35,0,$Q35*$D35)*(1-$F35) -> 0 | AB35: =SUM(R35:AA35) -> 0
A36: =A26 -> Application Server | C36: =C26 -> 46.82 | D36: =D26 -> 9.36 | E36: =E26 -> 2 | F36: =F26 -> 0.5 | G36: =G26 -> PVU | H36: =H26 -> core | I36: =I26 -> 120 | J36: =J35 -> 0.33333333 | K36: =K35 -> 20 | L36: =L35 -> 20 | O36: =_xlfn.XLOOKUP($H36,$J$23:$L$23,$J36:$L36) -> 20 | P36: PVU | Q36: =I36*O36 -> 2400 | R36: =$Q36*$C36*(1-$F36) -> 56184 | W36: =IF(W$9<$E36,0,$Q36*$D36)*(1-$F36) -> 0 | X36: =IF(X$9<$E36,0,$Q36*$D36)*(1-$F36) -> 11232 | Y36: =IF(Y$9<$E36,0,$Q36*$D36)*(1-$F36) -> 11232 | Z36: =IF(Z$9<$E36,0,$Q36*$D36)*(1-$F36) -> 11232 | AA36: =IF(AA$9<$E36,0,$Q36*$D36)*(1-$F36) -> 11232 | AB36: =SUM(R36:AA36) -> 101112
A37: =A27 -> DB | C37: =C27 -> 0 | D37: =D27 -> 8500 | E37: =E27 -> 1 | F37: =F27 -> 0 | G37: =G27 -> server | H37: =H27 -> server | I37: =I27 -> 1 | J37: =J36 -> 0.33333333 | K37: =K36 -> 20 | L37: =L36 -> 20 | O37: =_xlfn.XLOOKUP($H37,$J$23:$L$23,$J37:$L37) -> 0.33333333 | P37: core | Q37: =I37*O37 -> 0.33333333 | R37: =$Q37*$C37*(1-$F37) -> 0 | W37: =IF(W$9<$E37,0,$Q37*$D37)*(1-$F37) -> 2833.3333 | X37: =IF(X$9<$E37,0,$Q37*$D37)*(1-$F37) -> 2833.3333 | Y37: =IF(Y$9<$E37,0,$Q37*$D37)*(1-$F37) -> 2833.3333 | Z37: =IF(Z$9<$E37,0,$Q37*$D37)*(1-$F37) -> 2833.3333 | AA37: =IF(AA$9<$E37,0,$Q37*$D37)*(1-$F37) -> 2833.3333 | AB37: =SUM(R37:AA37) -> 14166.667
A38: =A28 -> Data Replication Tools | C38: =C28 -> 0 | D38: =D28 -> 3000 | E38: =E28 -> 1 | F38: =F28 -> 0.5 | G38: =G28 -> core | H38: =H28 -> core | I38: =I28 -> 1 | J38: =J37 -> 0.33333333 | K38: =K37 -> 20 | L38: =L37 -> 20 | O38: =_xlfn.XLOOKUP($H38,$J$23:$L$23,$J38:$L38) -> 20 | P38: core | Q38: =I38*O38 -> 20 | R38: =$Q38*$C38*(1-$F38) -> 0 | W38: =IF(W$9<$E38,0,$Q38*$D38)*(1-$F38) -> 30000 | X38: =IF(X$9<$E38,0,$Q38*$D38)*(1-$F38) -> 30000 | Y38: =IF(Y$9<$E38,0,$Q38*$D38)*(1-$F38) -> 30000 | Z38: =IF(Z$9<$E38,0,$Q38*$D38)*(1-$F38) -> 30000 | AA38: =IF(AA$9<$E38,0,$Q38*$D38)*(1-$F38) -> 30000 | AB38: =SUM(R38:AA38) -> 150000
A39: =A29 -> Monitoring Tools | C39: =C29 -> 5000 | D39: =D29 -> 1000 | E39: =E29 -> 2 | F39: =F29 -> 0.4 | G39: =G29 -> server | H39: =H29 -> server | I39: =I29 -> 1 | J39: =J38 -> 0.33333333 | K39: =K38 -> 20 | L39: =L38 -> 20 | O39: =_xlfn.XLOOKUP($H39,$J$23:$L$23,$J39:$L39) -> 0.33333333 | P39: server | Q39: =I39*O39 -> 0.33333333 | R39: =$Q39*$C39*(1-$F39) -> 1000 | W39: =IF(W$9<$E39,0,$Q39*$D39)*(1-$F39) -> 0 | X39: =IF(X$9<$E39,0,$Q39*$D39)*(1-$F39) -> 200 | Y39: =IF(Y$9<$E39,0,$Q39*$D39)*(1-$F39) -> 200 | Z39: =IF(Z$9<$E39,0,$Q39*$D39)*(1-$F39) -> 200 | AA39: =IF(AA$9<$E39,0,$Q39*$D39)*(1-$F39) -> 200 | AB39: =SUM(R39:AA39) -> 1800
A40: =A30 -> Security Tools | C40: =C30 -> 5000 | D40: =D30 -> 1000 | E40: =E30 -> 2 | F40: =F30 -> 0.4 | G40: =G30 -> server | H40: =H30 -> server | I40: =I30 -> 1 | J40: =J39 -> 0.33333333 | K40: =K39 -> 20 | L40: =L39 -> 20 | O40: =_xlfn.XLOOKUP($H40,$J$23:$L$23,$J40:$L40) -> 0.33333333 | P40: server | Q40: =I40*O40 -> 0.33333333 | R40: =$Q40*$C40*(1-$F40) -> 1000 | W40: =IF(W$9<$E40,0,$Q40*$D40)*(1-$F40) -> 0 | X40: =IF(X$9<$E40,0,$Q40*$D40)*(1-$F40) -> 200 | Y40: =IF(Y$9<$E40,0,$Q40*$D40)*(1-$F40) -> 200 | Z40: =IF(Z$9<$E40,0,$Q40*$D40)*(1-$F40) -> 200 | AA40: =IF(AA$9<$E40,0,$Q40*$D40)*(1-$F40) -> 200 | AB40: =SUM(R40:AA40) -> 1800
Q41: DEV | R41: =SUM(R34:R40) -> 58184 | S41: =SUM(S34:S40) -> 0 | T41: =SUM(T34:T40) -> 0 | U41: =SUM(U34:U40) -> 0 | V41: =SUM(V34:V40) -> 0 | W41: =SUM(W34:W40) -> 128833.33 | X41: =SUM(X34:X40) -> 140465.33 | Y41: =SUM(Y34:Y40) -> 140465.33 | ... AB41: =SUM(AB34:AB40) -> 748878.67
A43: Test | C43: Acquisition/ Capital Cost | D43: Maintenance/ Operating Cost | E43: Starting Year of Maint charges | F43: Discount % | G43: Unit of Measure | H43: Measured by | I43: conversion factor | J43: server | K43: socket | L43: core | O43: count | P43: Unit of Measure | Q43: Units | R43: 1 | S43: 2 | T43: 3 | U43: 4 | V43: 5 | W43: 1 | X43: 2 | Y43: 3 | Z43: 4 | AA43: 5 | AB43: TOT
A44: =A24 -> OS | C44: =C24 -> 0 | D44: =D24 -> 6000 | E44: =E24 -> 1 | F44: =F24 -> 0.2 | G44: =G34 -> core | H44: =H34 -> core | I44: =I34 -> 1 | J44: =$O$12 -> 0.33333333 | K44: =$P$12 -> 20 | L44: =$Q$12 -> 20 | O44: =_xlfn.XLOOKUP($H44,$J$23:$L$23,$J44:$L44) -> 20 | P44: socket | Q44: =I44*O44 -> 20 | R44: =$Q44*$C44*(1-$F44) -> 0 | W44: =IF(W$9<$E44,0,$Q44*$D44)*(1-$F44) -> 96000 | X44: =IF(X$9<$E44,0,$Q44*$D44)*(1-$F44) -> 96000 | Y44: =IF(Y$9<$E44,0,$Q44*$D44)*(1-$F44) -> 96000 | Z44: =IF(Z$9<$E44,0,$Q44*$D44)*(1-$F44) -> 96000 | AA44: =IF(AA$9<$E44,0,$Q44*$D44)*(1-$F44) -> 96000 | AB44: =SUM(R44:AA44) -> 480000
A45: =A25 -> VM | C45: =C25 -> 0 | D45: =D25 -> 0 | E45: =E25 -> 2 | F45: =F25 -> 0.2 | G45: =G35 -> core | H45: =H35 -> core | I45: =I35 -> 1 | J45: =J44 -> 0.33333333 | K45: =K44 -> 20 | L45: =L44 -> 20 | O45: =_xlfn.XLOOKUP($H45,$J$23:$L$23,$J45:$L45) -> 20 | P45: socket | Q45: =I45*O45 -> 20 | R45: =$Q45*$C45*(1-$F45) -> 0 | W45: =IF(W$9<$E45,0,$Q45*$D45)*(1-$F45) -> 0 | X45: =IF(X$9<$E45,0,$Q45*$D45)*(1-$F45) -> 0 | Y45: =IF(Y$9<$E45,0,$Q45*$D45)*(1-$F45) -> 0 | Z45: =IF(Z$9<$E45,0,$Q45*$D45)*(1-$F45) -> 0 | AA45: =IF(AA$9<$E45,0,$Q45*$D45)*(1-$F45) -> 0 | AB45: =SUM(R45:AA45) -> 0
A46: =A26 -> Application Server | C46: =C26 -> 46.82 | D46: =D26 -> 9.36 | E46: =E26 -> 2 | F46: =F26 -> 0.5 | G46: =G36 -> PVU | H46: =H36 -> core | I46: =I36 -> 120 | J46: =J45 -> 0.33333333 | K46: =K45 -> 20 | L46: =L45 -> 20 | O46: =_xlfn.XLOOKUP($H46,$J$23:$L$23,$J46:$L46) -> 20 | P46: PVU | Q46: =I46*O46 -> 2400 | R46: =$Q46*$C46*(1-$F46) -> 56184 | W46: =IF(W$9<$E46,0,$Q46*$D46)*(1-$F46) -> 0 | X46: =IF(X$9<$E46,0,$Q46*$D46)*(1-$F46) -> 11232 | Y46: =IF(Y$9<$E46,0,$Q46*$D46)*(1-$F46) -> 11232 | Z46: =IF(Z$9<$E46,0,$Q46*$D46)*(1-$F46) -> 11232 | AA46: =IF(AA$9<$E46,0,$Q46*$D46)*(1-$F46) -> 11232 | AB46: =SUM(R46:AA46) -> 101112
A47: =A27 -> DB | C47: =C27 -> 0 | D47: =D27 -> 8500 | E47: =E27 -> 1 | F47: =F27 -> 0 | G47: =G37 -> server | H47: =H37 -> server | I47: =I37 -> 1 | J47: =J46 -> 0.33333333 | K47: =K46 -> 20 | L47: =L46 -> 20 | O47: =_xlfn.XLOOKUP($H47,$J$23:$L$23,$J47:$L47) -> 0.33333333 | P47: core | Q47: =I47*O47 -> 0.33333333 | R47: =$Q47*$C47*(1-$F47) -> 0 | W47: =IF(W$9<$E47,0,$Q47*$D47)*(1-$F47) -> 2833.3333 | X47: =IF(X$9<$E47,0,$Q47*$D47)*(1-$F47) -> 2833.3333 | Y47: =IF(Y$9<$E47,0,$Q47*$D47)*(1-$F47) -> 2833.3333 | Z47: =IF(Z$9<$E47,0,$Q47*$D47)*(1-$F47) -> 2833.3333 | AA47: =IF(AA$9<$E47,0,$Q47*$D47)*(1-$F47) -> 2833.3333 | AB47: =SUM(R47:AA47) -> 14166.667
A48: =A28 -> Data Replication Tools | C48: =C28 -> 0 | D48: =D28 -> 3000 | E48: =E28 -> 1 | F48: =F28 -> 0.5 | G48: =G38 -> core | H48: =H38 -> core | I48: =I38 -> 1 | J48: =J47 -> 0.33333333 | K48: =K47 -> 20 | L48: =L47 -> 20 | O48: =_xlfn.XLOOKUP($H48,$J$23:$L$23,$J48:$L48) -> 20 | P48: core | Q48: =I48*O48 -> 20 | R48: =$Q48*$C48*(1-$F48) -> 0 | W48: =IF(W$9<$E48,0,$Q48*$D48)*(1-$F48) -> 30000 | X48: =IF(X$9<$E48,0,$Q48*$D48)*(1-$F48) -> 30000 | Y48: =IF(Y$9<$E48,0,$Q48*$D48)*(1-$F48) -> 30000 | Z48: =IF(Z$9<$E48,0,$Q48*$D48)*(1-$F48) -> 30000 | AA48: =IF(AA$9<$E48,0,$Q48*$D48)*(1-$F48) -> 30000 | AB48: =SUM(R48:AA48) -> 150000
...

Sheet TCO comparison
B1: Workload [TPS]= | C1: =sizing!C2 -> 8000
B3: x86 | C3: Environments | K3: LinuxONE | L3: Environments
A4: ='x86 TCO'!A5 -> Rack HPE w Xeon Gold 6230 20C 2.10GHz (2 Chips, 40 Cores) | C4: Prod | D4: Dev | E4: Test | F4: PreProd/QA | G4: DR | H4: Tot by Comp | L4: Prod | M4: Dev | N4: Test | O4: PreProd/QA | P4: DR | Q4: Tot by Comp
A5: Components | B5: Hardware | C5: ='x86 TCO'!AB19 -> 134400 | D5: ='x86 TCO'!AB20 -> 67200 | E5: ='x86 TCO'!AB21 -> 67200 | F5: ='x86 TCO'!AB22 -> 134400 | G5: ='x86 TCO'!AB23 -> 268800 | H5: =SUM(C5:G5) -> 672000 | J5: Components | K5: Hardware | L5: ='LinuxONE TCO'!AB10 -> 1848000 | M5: ='LinuxONE TCO'!AB11 -> 924000 | N5: ='LinuxONE TCO'!AB12 -> 924000 | O5: ='LinuxONE TCO'!AB13 -> 1848000 | P5: ='LinuxONE TCO'!AB14 -> 336000 | Q5: =SUM(L5:P5) -> 5880000
B6: Software | C6: ='x86 TCO'!AB35 -> 2612184 | D6: ='x86 TCO'!AB45 -> 1306092 | E6: ='x86 TCO'!AB55 -> 1306092 | F6: ='x86 TCO'!AB65 -> 2612184 | G6: ='x86 TCO'!AB75 -> 5224368 | H6: =SUM(C6:G6) -> 13060920 | K6: Software | L6: ='LinuxONE TCO'!AB31 -> 1497757.3 | M6: ='LinuxONE TCO'!AB41 -> 748878.67 | N6: ='LinuxONE TCO'!AB51 -> 748878.67 | O6: ='LinuxONE TCO'!AB61 -> 1497757.3 | P6: ='LinuxONE TCO'!AB71 -> 0 | Q6: =SUM(L6:P6) -> 4493272
B7: People | C7: ='x86 TCO'!AB86 -> 1000000 | H7: =SUM(C7:G7) -> 1000000 | K7: People | L7: ='LinuxONE TCO'!AB82 -> 100000 | Q7: =SUM(L7:P7) -> 100000
B8: Network | C8: ='x86 TCO'!AB90 -> 82320 | D8: ='x86 TCO'!AB91 -> 41160 | E8: ='x86 TCO'!AB92 -> 41160 | F8: ='x86 TCO'!AB93 -> 82320 | G8: ='x86 TCO'!AB94 -> 164640 | H8: =SUM(C8:G8) -> 411600 | K8: Network | L8: ='LinuxONE TCO'!AB86 -> 9146.6667 | M8: ='LinuxONE TCO'!AB87 -> 4573.3333 | N8: ='LinuxONE TCO'!AB88 -> 4573.3333 | O8: ='LinuxONE TCO'!AB89 -> 9146.6667 | P8: ='LinuxONE TCO'!AB90 -> 0 | Q8: =SUM(L8:P8) -> 27440
B9: Space | C9: ='x86 TCO'!AB99 -> 46020 | D9: ='x86 TCO'!AB100 -> 15953.6 | E9: ='x86 TCO'!AB101 -> 15953.6 | F9: ='x86 TCO'!AB102 -> 31907.2 | G9: ='x86 TCO'!AB103 -> 76700 | H9: =SUM(C9:G9) -> 186534.4 | K9: Space | L9: ='LinuxONE TCO'!AB95 -> 28634.667 | M9: ='LinuxONE TCO'!AB96 -> 14317.333 | N9: ='LinuxONE TCO'!AB97 -> 14317.333 | O9: ='LinuxONE TCO'!AB98 -> 28634.667 | P9: ='LinuxONE TCO'!AB99 -> 0 | Q9: =SUM(L9:P9) -> 85904
B10: Electricity | C10: ='x86 TCO'!AB108 -> 99233.28 | D10: ='x86 TCO'!AB109 -> 49616.64 | E10: ='x86 TCO'!AB110 -> 49616.64 | F10: ='x86 TCO'!AB111 -> 99233.28 | G10: ='x86 TCO'!AB112 -> 198466.56 | H10: =SUM(C10:G10) -> 496166.4 | K10: Electricity | L10: ='LinuxONE TCO'!AB104 -> 16321.263 | M10: ='LinuxONE TCO'!AB105 -> 8160.6316 | N10: ='LinuxONE TCO'!AB106 -> 8160.6316 | O10: ='LinuxONE TCO'!AB107 -> 16321.263 | P10: ='LinuxONE TCO'!AB108 -> 0 | Q10: =SUM(L10:P10) -> 48963.789
B11: Total by Env | C11: =SUM(C5:C10) -> 3974157.3 | D11: =SUM(D5:D10) -> 1480022.2 | E11: =SUM(E5:E10) -> 1480022.2 | F11: =SUM(F5:F10) -> 2960044.5 | G11: =SUM(G5:G10) -> 5932974.6 | H11: =SUM(H5:H10) -> 15827221 | K11: Total by Env | L11: =SUM(L5:L10) -> 3499859.9 | M11: =SUM(M5:M10) -> 1699930 | N11: =SUM(N5:N10) -> 1699930 | O11: =SUM(O5:O10) -> 3399859.9 | P11: =SUM(P5:P10) -> 336000 | Q11: =SUM(Q5:Q10) -> 10635580
P12: Savings = | Q12: =(H11-Q11)/H11 -> 0.32801975
B15: Hardware | C15: Software | D15: People | E15: Network | F15: Facilities | G15: DR | H15: TOT
A16: =B3 -> x86 | B16: =SUM(C5:F5) -> 403200 | C16: =SUM(C6:F6) -> 7836552 | D16: =SUM(C7:F7) -> 1000000 | E16: =SUM(#REF!) -> #REF! | F16: =SUM(#REF!) -> #REF! | G16: =G11 -> 5932974.6 | H16: =SUM(B16:G16) -> #REF!
A17: =K3 -> LinuxONE | B17: =SUM(L5:O5) -> 5544000 | C17: =SUM(L6:O6) -> 4493272 | D17: =SUM(L7:O7) -> 100000 | E17: =SUM(#REF!) -> #REF! | F17: =SUM(#REF!) -> #REF! | G17: =P11 -> 336000 | H17: =SUM(B17:G17) -> #REF!
B19: Cumulative Costs | C19: Year 1 | D19: Year 2 | E19: Year 3 | F19: Year 4 | G19: Year 5
B20: =B3 -> x86 | C20: ='x86 TCO'!W126 -> 5518980.2 | D20: ='x86 TCO'!X126 -> 8048040.3 | E20: ='x86 TCO'!Y126 -> 10577100 | F20: ='x86 TCO'!Z126 -> 13202161 | G20: ='x86 TCO'!AA126 -> 15827221
B21: =K3 -> LinuxONE | C21: ='LinuxONE TCO'!W131 -> 6088677.6 | D21: ='LinuxONE TCO'!X131 -> 6980403.1 | E21: ='LinuxONE TCO'!Y131 -> 7872128.7 | F21: ='LinuxONE TCO'!Z131 -> 9253854.2 | G21: ='LinuxONE TCO'!AA131 -> 10635580
B31: TCA (1st year) | C31: Hardware | D31: Software | E31: TOT
B32: x86 | C32: ='x86 TCO'!R24 -> 480000 | D32: ='x86 TCO'!R35 -> 561288 | E32: =SUM(C32:D32) -> 1041288
B33: LinuxONE | C33: ='LinuxONE TCO'!R15 -> 4900000 | D33: ='LinuxONE TCO'!R31 -> 116368 | E33: =SUM(C33:D33) -> 5016368 | F33: =E33/E32 -> 4.8174645

Sheet Data
A1: Warmup Tasks | B1: € - $ Rate 25/03/21 | C1: 1.18
A3: Server
A4: Server Model | B4: Acquisition Cost | C4: Maintenance/ Operating Cost | D4: Starting Year of Maint | E4: Discount % | F4: # of Cores per Server | G4: # of Sockets | H4: # of Cores per socket | I4: # of "boxes" per Rack | J4: kW | K4: PVU* | L4: Source
A5: Rack DELL w Xeon Gold 5220 18C 2.20GHz (4 Chips, 72 Cores) | B5: =ROUND(24549/C1, -2) -> 20800 | C5: =B5*0.2 -> 4160 | D5: 4 | E5: 0.37 | F5: =G5*H5 -> 72 | G5: 4 | H5: 18 | I5: 10 | J5: 1.1 | K5: 100 | L5: https://www.dell.com/en-us/work/shop/cty/pdp/spd/poweredge-r940/pe_r940_12229_vi_vp?configurationid=98797f27-d554-4678-b6d3-e9240afd88af
A6: Rack HPE w Xeon Gold 6230 20C 2.10GHz (2 Chips, 40 Cores) | B6: 8000 | C6: =B6*0.2 -> 1600 | D6: 4 | E6: 0 | F6: =G6*H6 -> 40 | G6: 2 | H6: 20 | I6: 15 | J6: 1.6 | K6: 70 | L6: https://buy.hpe.com/it/it/servers/proliant-dl-servers/proliant-dl500-servers/proliant-dl560-server/hpe-proliant-dl560-gen10-server/hpe-proliant-dl560-gen10-6230-2-1ghz-20-core-2p-128gb-r-8sff-2x1600w-rps-server/p/P40455-B21
A8: * https://www.ibm.com/software/passportadvantage/pvu_licensing_for_customers.html
A10: Application Server
A12: {=INDEX(A15:A21,$G$12)} -> IBM WebSphere | B12: {=INDEX(B15:B21,$G$12)} -> 46.82 | C12: {=INDEX(C15:C21,$G$12)} -> 9.36 | D12: {=INDEX(D15:D21,$G$12)} -> 2 | E12: {=INDEX(F15:F21,$G$12)} -> PVU | F12: {=INDEX(G15:G21,$G$12)} -> core | G12: =MATCH("S",O15:O21) -> 2
A13: Commercial Application Server
A14: Name | B14: Acquisition Cost | C14: Maintenance/ Operating Cost | D14: Starting Year of yearly charges | E14: Discount % | F14: Unit of Measure | G14: Measured by | H14: conversion factor | I14: Source
A15: WebLogic Server Enterprise Edition | B15: =ROUND(25000/C1, -2) -> 21200 | C15: =ROUND(5500/C1, -2) -> 4700 | D15: 1 | E15: 0 | F15: core | G15: core | H15: 0.5 | I15: https://www.oracle.com/assets/technology-price-list-070617.pdf | O15: 0
A16: IBM WebSphere | B16: =ROUND(55.25/C1, 2) -> 46.82 | C16: =ROUND(B16*20/100, 2) -> 9.36 | D16: 2 | E16: 0 | F16: PVU | G16: core | H16: * | I16: https://reviews.financesonline.com/p/ibm-webspehre/ | O16: S
A18: Open Source Application Server
A19: Name | B19: Acquisition Cost | C19: Maintenance/ Operating Cost | D19: Starting Year of yearly charges | E19: Discount % | F19: Unit of Measure | G19: Measured by | H19: conversion factor | I19: Source
A20: JBoss Enterprise Application Platform | B20: 0 | C20: =ROUND(12000/C1, -2) -> 10200 | D20: 1 | E20: 0 | F20: core | G20: core | H20: 0.0625 | I20: https://www.redhat.com/en/store/red-hat-jboss-enterprise-application-platform | O20: 0
A21: Payara Server Enterprise | B21: 0 | C21: Contact us | D21: - | E21: - | F21: - | G21: - | H21: - | I21: https://www.payara.fish/page/payara-enterprise-downloads/ | O21: 0
A23: Database
A25: {=INDEX(A28:A34,$G$25)} -> MongoDB | B25: {=INDEX(B28:B34,$G$25)} -> 0 | C25: {=INDEX(C28:C34,$G$25)} -> 8500 | D25: {=INDEX(D28:D34,$G$25)} -> 1 | E25: {=INDEX(F28:F34,$G$25)} -> server | F25: {=INDEX(G28:G34,$G$25)} -> server | G25: =MATCH("S",R28:R34) -> 6
A26: Commercial Database
A27: Name | B27: Acquisition Cost | C27: Maintenance/ Operating Cost | D27: Starting Year of yearly charges | E27: Discount % | F27: Unit of Measure | G27: Measured by | H27: conversion factor | I27: Data replication tool | J27: Source
A28: Oracle Database Enterprise Edition | B28: =ROUND(47500/C1, -2) -> 40300 | C28: =ROUND(10450/C1, -2) -> 8900 | D28: 1 | E28: 0 | F28: core | G28: core | H28: 0.5 | I28: =_xlfn.CONCAT(ROUND(3500/C1,-2), " / stream") -> 3000 / stream | J28: https://www.oracle.com/assets/technology-price-list-070617.pdf | R28: 0
A29: Microsoft SQL Server 2019 | B29: =ROUND(13748/C1, -2) -> 11700 | C29: =B29*20/100 -> 2340 | D29: 1 | E29: 0 | F29: core | G29: core | H29: 0.5 | I29: A30 | J29: https://www.microsoft.com/en-us/sql-server/sql-server-2019-pricing | R29: 0
A31: Open Source Database
A32: Name | B32: Acquisition Cost | C32: Maintenance/ Operating Cost | D32: Starting Year of yearly charges | E32: Discount % | F32: Unit of Measure | G32: Measured by | H32: conversion factor | I32: Data replication tool | J32: Source
A33: MongoDB | B33: 0 | C33: =ROUND(10000/C1,-2) -> 8500 | D33: 1 | E33: 0 | F33: server | G33: server | H33: 1 | I33: A31 | J33: https://www.pcworld.com/article/2466460/mongodb-adds-support-option-for-community-edition-of-its-nosql-database.html | R33: S
A34: SQLite | B34: 0 | C34: =ROUND(85000/C1,-2) -> 72000 | D34: 1 | E34: 0 | F34: year | G34: year | H34: 1 | I34: A32 | J34: https://www.sqlite.org/prosupport.html | R34: 0
A36: https://docs.microsoft.com/it-it/sql/relational-databases/replication/configure-publishing-and-distribution?view=sql-server-ver15 | F36: 0 | H36: All conversion factors are for x86 cores
A37: https://docs.mongodb.com/manual/tutorial/deploy-replica-set/ | F37: 0 | H37: Remember to change discount and conversion factor in each TCO
A38: https://github.com/benbjohnson/litestream | F38: 0
A40: Another reference for MongoDB
A41: https://www.reddit.com/r/mongodb/comments/a3xvaw/mongodb_enterprise_pricing/
C44: TCO at 5y 1 fault by TPS
C46: 100 | D46: 200 | E46: 500 | F46: 1000
B47: x86 | C47: 859910.94 | D47: 1042588.4 | E47: 2069664.3 | F47: 3492667.7
B48: LinuxONE | C48: 1484198.5 | D48: 1484198.5 | E48: 1722780.3 | F48: 2129362.1
